<?xml version="1.0" encoding="utf-8" standalone="yes" ?>
<rss version="2.0" xmlns:atom="http://www.w3.org/2005/Atom">
  <channel>
    <title>Junit on geraldo.dev</title>
    <link>/tags/junit/</link>
    <description>Recent content in Junit on geraldo.dev</description>
    <generator>Hugo -- gohugo.io</generator>
    <language>pt-br</language>
    <copyright>&amp;copy; 2019 Geraldo Ribeiro</copyright>
    <lastBuildDate>Tue, 12 Nov 2019 00:00:00 -0300</lastBuildDate>
    
	<atom:link href="/tags/junit/index.xml" rel="self" type="application/rss+xml" />
    
    
    <item>
      <title>Testando exceções com junit</title>
      <link>/posts/junit-excecao/</link>
      <pubDate>Tue, 12 Nov 2019 00:00:00 -0300</pubDate>
      
      <guid>/posts/junit-excecao/</guid>
      <description>Este artigo apresenta uma visão suscinta sobre testes de exceção com JUnit usando o idioma try/fail/catch, o parâmetro expected da anotação @Test e a anotação @Rule. Cada um dos métodos apresenta prós e contras.
Usando bloco try/catch @Test public void example1() { try { find(&amp;#34;função que deveria lançar uma exceção&amp;#34;); fail(); // Ponto que nunca deveria ser alcançado quando o teste passar  } catch (NotFoundException e) { assertThat(e.getMessage(), containsString(&amp;#34;algo que indique que a exceção certa ocorreu&amp;#34;)); } // .</description>
    </item>
    
  </channel>
</rss>